2024-12-23 12:17:51,135 - root - ERROR - Error during transcription
Traceback (most recent call last):
  File "/Users/priyamsekra/my_code/DATA 2/AIML_Project_Linkdin/jarvic-health-api/app/main.py", line 67, in process_audio
    with open(audio_file_path, "rb") as audio_file:
         ^^^^^^^^^^^^^^^^^^^^^^^^^^^
FileNotFoundError: [Errno 2] No such file or directory: 'audio.mp3'
2024-12-24 01:08:32,462 - root - ERROR - Error downloading audio: name 'requests' is not defined
Traceback (most recent call last):
  File "/Users/priyamsekra/my_code/DATA 2/AIML_Project_Linkdin/jarvic-health-api/app/main.py", line 62, in process_audio
    response = requests.get(input.audio_link, stream=True)
               ^^^^^^^^
NameError: name 'requests' is not defined
2024-12-24 01:08:32,465 - root - ERROR - Global exception handler caught: name 'os' is not defined
Traceback (most recent call last):
  File "/Users/priyamsekra/my_code/DATA 2/AIML_Project_Linkdin/jarvic-health-api/app/main.py", line 62, in process_audio
    response = requests.get(input.audio_link, stream=True)
               ^^^^^^^^
NameError: name 'requests' is not defined

During handling of the above exception, another exception occurred:

Traceback (most recent call last):
  File "/Users/priyamsekra/my_code/DATA 2/AIML_Project_Linkdin/venv/lib/python3.11/site-packages/starlette/middleware/errors.py", line 165, in __call__
    await self.app(scope, receive, _send)
  File "/Users/priyamsekra/my_code/DATA 2/AIML_Project_Linkdin/venv/lib/python3.11/site-packages/starlette/middleware/exceptions.py", line 62, in __call__
    await wrap_app_handling_exceptions(self.app, conn)(scope, receive, send)
  File "/Users/priyamsekra/my_code/DATA 2/AIML_Project_Linkdin/venv/lib/python3.11/site-packages/starlette/_exception_handler.py", line 53, in wrapped_app
    raise exc
  File "/Users/priyamsekra/my_code/DATA 2/AIML_Project_Linkdin/venv/lib/python3.11/site-packages/starlette/_exception_handler.py", line 42, in wrapped_app
    await app(scope, receive, sender)
  File "/Users/priyamsekra/my_code/DATA 2/AIML_Project_Linkdin/venv/lib/python3.11/site-packages/starlette/routing.py", line 715, in __call__
    await self.middleware_stack(scope, receive, send)
  File "/Users/priyamsekra/my_code/DATA 2/AIML_Project_Linkdin/venv/lib/python3.11/site-packages/starlette/routing.py", line 735, in app
    await route.handle(scope, receive, send)
  File "/Users/priyamsekra/my_code/DATA 2/AIML_Project_Linkdin/venv/lib/python3.11/site-packages/starlette/routing.py", line 288, in handle
    await self.app(scope, receive, send)
  File "/Users/priyamsekra/my_code/DATA 2/AIML_Project_Linkdin/venv/lib/python3.11/site-packages/starlette/routing.py", line 76, in app
    await wrap_app_handling_exceptions(app, request)(scope, receive, send)
  File "/Users/priyamsekra/my_code/DATA 2/AIML_Project_Linkdin/venv/lib/python3.11/site-packages/starlette/_exception_handler.py", line 53, in wrapped_app
    raise exc
  File "/Users/priyamsekra/my_code/DATA 2/AIML_Project_Linkdin/venv/lib/python3.11/site-packages/starlette/_exception_handler.py", line 42, in wrapped_app
    await app(scope, receive, sender)
  File "/Users/priyamsekra/my_code/DATA 2/AIML_Project_Linkdin/venv/lib/python3.11/site-packages/starlette/routing.py", line 73, in app
    response = await f(request)
               ^^^^^^^^^^^^^^^^
  File "/Users/priyamsekra/my_code/DATA 2/AIML_Project_Linkdin/venv/lib/python3.11/site-packages/fastapi/routing.py", line 301, in app
    raw_response = await run_endpoint_function(
                   ^^^^^^^^^^^^^^^^^^^^^^^^^^^^
  File "/Users/priyamsekra/my_code/DATA 2/AIML_Project_Linkdin/venv/lib/python3.11/site-packages/fastapi/routing.py", line 212, in run_endpoint_function
    return await dependant.call(**values)
           ^^^^^^^^^^^^^^^^^^^^^^^^^^^^^^
  File "/Users/priyamsekra/my_code/DATA 2/AIML_Project_Linkdin/jarvic-health-api/app/main.py", line 71, in process_audio
    if os.path.exists(audio_file_path):
       ^^
NameError: name 'os' is not defined
2024-12-24 01:09:10,215 - root - ERROR - Error downloading audio: Invalid URL 'koagiu': No scheme supplied. Perhaps you meant https://koagiu?
Traceback (most recent call last):
  File "/Users/priyamsekra/my_code/DATA 2/AIML_Project_Linkdin/jarvic-health-api/app/main.py", line 64, in process_audio
    response = requests.get(input.audio_link, stream=True)
               ^^^^^^^^^^^^^^^^^^^^^^^^^^^^^^^^^^^^^^^^^^^
  File "/Users/priyamsekra/my_code/DATA 2/AIML_Project_Linkdin/venv/lib/python3.11/site-packages/requests/api.py", line 73, in get
    return request("get", url, params=params, **kwargs)
           ^^^^^^^^^^^^^^^^^^^^^^^^^^^^^^^^^^^^^^^^^^^^
  File "/Users/priyamsekra/my_code/DATA 2/AIML_Project_Linkdin/venv/lib/python3.11/site-packages/requests/api.py", line 59, in request
    return session.request(method=method, url=url, **kwargs)
           ^^^^^^^^^^^^^^^^^^^^^^^^^^^^^^^^^^^^^^^^^^^^^^^^^
  File "/Users/priyamsekra/my_code/DATA 2/AIML_Project_Linkdin/venv/lib/python3.11/site-packages/requests/sessions.py", line 575, in request
    prep = self.prepare_request(req)
           ^^^^^^^^^^^^^^^^^^^^^^^^^
  File "/Users/priyamsekra/my_code/DATA 2/AIML_Project_Linkdin/venv/lib/python3.11/site-packages/requests/sessions.py", line 484, in prepare_request
    p.prepare(
  File "/Users/priyamsekra/my_code/DATA 2/AIML_Project_Linkdin/venv/lib/python3.11/site-packages/requests/models.py", line 367, in prepare
    self.prepare_url(url, params)
  File "/Users/priyamsekra/my_code/DATA 2/AIML_Project_Linkdin/venv/lib/python3.11/site-packages/requests/models.py", line 438, in prepare_url
    raise MissingSchema(
requests.exceptions.MissingSchema: Invalid URL 'koagiu': No scheme supplied. Perhaps you meant https://koagiu?
2024-12-24 01:09:10,216 - root - ERROR - Error during transcription
Traceback (most recent call last):
  File "/Users/priyamsekra/my_code/DATA 2/AIML_Project_Linkdin/jarvic-health-api/app/main.py", line 83, in process_audio
    transcription = client.audio.transcriptions.create(
                    ^^^^^^
NameError: name 'client' is not defined
2024-12-24 01:16:00,703 - root - ERROR - Error downloading audio: Invalid URL 'koagiu': No scheme supplied. Perhaps you meant https://koagiu?
Traceback (most recent call last):
  File "/Users/priyamsekra/my_code/DATA 2/AIML_Project_Linkdin/jarvic-health-api/app/main.py", line 96, in process_audio
    response = requests.get(input.audio_link, stream=True)
               ^^^^^^^^^^^^^^^^^^^^^^^^^^^^^^^^^^^^^^^^^^^
  File "/Users/priyamsekra/my_code/DATA 2/AIML_Project_Linkdin/venv/lib/python3.11/site-packages/requests/api.py", line 73, in get
    return request("get", url, params=params, **kwargs)
           ^^^^^^^^^^^^^^^^^^^^^^^^^^^^^^^^^^^^^^^^^^^^
  File "/Users/priyamsekra/my_code/DATA 2/AIML_Project_Linkdin/venv/lib/python3.11/site-packages/requests/api.py", line 59, in request
    return session.request(method=method, url=url, **kwargs)
           ^^^^^^^^^^^^^^^^^^^^^^^^^^^^^^^^^^^^^^^^^^^^^^^^^
  File "/Users/priyamsekra/my_code/DATA 2/AIML_Project_Linkdin/venv/lib/python3.11/site-packages/requests/sessions.py", line 575, in request
    prep = self.prepare_request(req)
           ^^^^^^^^^^^^^^^^^^^^^^^^^
  File "/Users/priyamsekra/my_code/DATA 2/AIML_Project_Linkdin/venv/lib/python3.11/site-packages/requests/sessions.py", line 484, in prepare_request
    p.prepare(
  File "/Users/priyamsekra/my_code/DATA 2/AIML_Project_Linkdin/venv/lib/python3.11/site-packages/requests/models.py", line 367, in prepare
    self.prepare_url(url, params)
  File "/Users/priyamsekra/my_code/DATA 2/AIML_Project_Linkdin/venv/lib/python3.11/site-packages/requests/models.py", line 438, in prepare_url
    raise MissingSchema(
requests.exceptions.MissingSchema: Invalid URL 'koagiu': No scheme supplied. Perhaps you meant https://koagiu?
